[WARNING] 2024-01-17 05:31:00 - PyNaCl is not installed, voice will NOT be supported
[WARNING] 2024-01-17 05:31:14 - PyNaCl is not installed, voice will NOT be supported
[ERROR] 2024-01-17 05:32:35 - An error occurred in Userinfo: 'ApplicationContext' object has no attribute 'mention'
Traceback (most recent call last):
  File "C:\Users\Olive\Documents\DiscordBot\cogs\userinfo.py", line 19, in userinfo
    description=f"{member.mention}",
                   ^^^^^^^^^^^^^^
AttributeError: 'ApplicationContext' object has no attribute 'mention'
[ERROR] 2024-01-17 05:39:34 - An error occurred in Unban: object BanIterator can't be used in 'await' expression
Traceback (most recent call last):
  File "C:\Users\Olive\Documents\DiscordBot\cogs\unban.py", line 23, in bans
    bans = await ctx.guild.bans()
           ^^^^^^^^^^^^^^^^^^^^^^
TypeError: object BanIterator can't be used in 'await' expression
[ERROR] 2024-01-17 05:45:10 - An error occurred in Unban: object BanIterator can't be used in 'await' expression
Traceback (most recent call last):
  File "C:\Users\Olive\Documents\DiscordBot\cogs\unban.py", line 23, in bans
    bans = await ctx.guild.bans()
           ^^^^^^^^^^^^^^^^^^^^^^
TypeError: object BanIterator can't be used in 'await' expression
[ERROR] 2024-01-17 05:46:53 - An error occurred in Unban: 'BanIterator' object is not iterable
Traceback (most recent call last):
  File "C:\Users\Olive\Documents\DiscordBot\cogs\unban.py", line 26, in bans
    for entry in bans:
TypeError: 'BanIterator' object is not iterable
[ERROR] 2024-01-17 05:52:05 - An error occurred in Unban: object BanIterator can't be used in 'await' expression
Traceback (most recent call last):
  File "C:\Users\Olive\Documents\DiscordBot\cogs\unban.py", line 23, in bans
    bans = await ctx.guild.bans()
           ^^^^^^^^^^^^^^^^^^^^^^
TypeError: object BanIterator can't be used in 'await' expression
[ERROR] 2024-01-17 05:53:04 - An error occurred in Unban: 'User' object has no attribute 'user'
Traceback (most recent call last):
  File "C:\Users\Olive\Documents\DiscordBot\cogs\unban.py", line 33, in bans
    value=f"Username: {entry.user.name}#{entry.user.discriminator}\nReason: {entry.reason}\nUser ID: {entry.user.id}\nIs Bot: {entry.user.bot}",
                       ^^^^^^^^^^
AttributeError: 'User' object has no attribute 'user'
[ERROR] 2024-01-17 05:54:58 - An error occurred in Unban: 'NoneType' object has no attribute 'id'
Traceback (most recent call last):
  File "C:\Users\Olive\Documents\DiscordBot\cogs\unban.py", line 54, in unban
    await ctx.guild.unban(member)
  File "C:\Users\Olive\Documents\DiscordBot\venv\Lib\site-packages\discord\guild.py", line 3117, in unban
    await self._state.http.unban(user.id, self.id, reason=reason)
                                 ^^^^^^^
AttributeError: 'NoneType' object has no attribute 'id'
[ERROR] 2024-01-17 05:55:35 - An error occurred in Unban: 'NoneType' object has no attribute 'id'
Traceback (most recent call last):
  File "C:\Users\Olive\Documents\DiscordBot\cogs\unban.py", line 54, in unban
    await ctx.guild.unban(member)
  File "C:\Users\Olive\Documents\DiscordBot\venv\Lib\site-packages\discord\guild.py", line 3117, in unban
    await self._state.http.unban(user.id, self.id, reason=reason)
                                 ^^^^^^^
AttributeError: 'NoneType' object has no attribute 'id'
[ERROR] 2024-01-17 06:29:03 - An error occurred in Unban: object BanIterator can't be used in 'await' expression
Traceback (most recent call last):
  File "C:\Users\Olive\Documents\DiscordBot\cogs\unban.py", line 52, in unban
    banned_users = await ctx.guild.bans()
                   ^^^^^^^^^^^^^^^^^^^^^^
TypeError: object BanIterator can't be used in 'await' expression
[WARNING] 2024-01-17 08:19:06 - We are being rate limited. Retrying in 0.30 seconds. Handled under the bucket "1124304903783841852:None:/channels/{channel_id}/messages/{message_id}"
[WARNING] 2024-01-17 08:19:06 - We are being rate limited. Retrying in 0.30 seconds. Handled under the bucket "1124304903783841852:None:/channels/{channel_id}/messages/{message_id}"
[WARNING] 2024-01-17 08:19:07 - We are being rate limited. Retrying in 0.38 seconds. Handled under the bucket "1124304903783841852:None:/channels/{channel_id}/messages/{message_id}"
[WARNING] 2024-01-17 08:19:08 - We are being rate limited. Retrying in 0.54 seconds. Handled under the bucket "1124304903783841852:None:/channels/{channel_id}/messages/{message_id}"
[WARNING] 2024-01-17 08:19:09 - We are being rate limited. Retrying in 0.59 seconds. Handled under the bucket "1124304903783841852:None:/channels/{channel_id}/messages/{message_id}"
[WARNING] 2024-01-17 08:19:10 - We are being rate limited. Retrying in 0.57 seconds. Handled under the bucket "1124304903783841852:None:/channels/{channel_id}/messages/{message_id}"
[WARNING] 2024-01-17 08:19:11 - We are being rate limited. Retrying in 0.30 seconds. Handled under the bucket "1124304903783841852:None:/channels/{channel_id}/messages/{message_id}"
[WARNING] 2024-01-17 08:19:12 - We are being rate limited. Retrying in 0.49 seconds. Handled under the bucket "1124304903783841852:None:/channels/{channel_id}/messages/{message_id}"
[WARNING] 2024-01-17 08:19:13 - We are being rate limited. Retrying in 0.60 seconds. Handled under the bucket "1124304903783841852:None:/channels/{channel_id}/messages/{message_id}"
[ERROR] 2024-01-17 08:46:08 - Task exception was never retrieved
future: <Task finished name='discord-ui-view-timeout-633304ed232e9b40e91389edfe7d26bd' coro=<Paginator.on_timeout() done, defined at C:\Users\Olive\Documents\DiscordBot\venv\Lib\site-packages\discord\ext\pages\pagination.py:575> exception=NotFound('404 Not Found (error code: 10008): Unknown Message')>
Traceback (most recent call last):
  File "C:\Users\Olive\Documents\DiscordBot\venv\Lib\site-packages\discord\ext\pages\pagination.py", line 583, in on_timeout
    await self.message.edit(
  File "C:\Users\Olive\Documents\DiscordBot\venv\Lib\site-packages\discord\interactions.py", line 1194, in edit
    return await self._state._interaction.edit_original_response(
           ^^^^^^^^^^^^^^^^^^^^^^^^^^^^^^^^^^^^^^^^^^^^^^^^^^^^^^
  File "C:\Users\Olive\Documents\DiscordBot\venv\Lib\site-packages\discord\interactions.py", line 428, in edit_original_response
    data = await adapter.edit_original_interaction_response(
           ^^^^^^^^^^^^^^^^^^^^^^^^^^^^^^^^^^^^^^^^^^^^^^^^^
  File "C:\Users\Olive\Documents\DiscordBot\venv\Lib\site-packages\discord\webhook\async_.py", line 219, in request
    raise NotFound(response, data)
discord.errors.NotFound: 404 Not Found (error code: 10008): Unknown Message
[ERROR] 2024-01-17 08:52:52 - Task exception was never retrieved
future: <Task finished name='discord-ui-view-timeout-de8e8dbcd6da8de5a87ccac40fb582af' coro=<Paginator.on_timeout() done, defined at C:\Users\Olive\Documents\DiscordBot\venv\Lib\site-packages\discord\ext\pages\pagination.py:575> exception=NotFound('404 Not Found (error code: 10008): Unknown Message')>
Traceback (most recent call last):
  File "C:\Users\Olive\Documents\DiscordBot\venv\Lib\site-packages\discord\ext\pages\pagination.py", line 583, in on_timeout
    await self.message.edit(
  File "C:\Users\Olive\Documents\DiscordBot\venv\Lib\site-packages\discord\interactions.py", line 1194, in edit
    return await self._state._interaction.edit_original_response(
           ^^^^^^^^^^^^^^^^^^^^^^^^^^^^^^^^^^^^^^^^^^^^^^^^^^^^^^
  File "C:\Users\Olive\Documents\DiscordBot\venv\Lib\site-packages\discord\interactions.py", line 428, in edit_original_response
    data = await adapter.edit_original_interaction_response(
           ^^^^^^^^^^^^^^^^^^^^^^^^^^^^^^^^^^^^^^^^^^^^^^^^^
  File "C:\Users\Olive\Documents\DiscordBot\venv\Lib\site-packages\discord\webhook\async_.py", line 219, in request
    raise NotFound(response, data)
discord.errors.NotFound: 404 Not Found (error code: 10008): Unknown Message
[ERROR] 2024-01-17 09:33:06 - Task exception was never retrieved
future: <Task finished name='discord-ui-view-timeout-78043da3e78c8949d9ad03ef5ea0d677' coro=<Paginator.on_timeout() done, defined at C:\Users\Olive\Documents\DiscordBot\venv\Lib\site-packages\discord\ext\pages\pagination.py:575> exception=NotFound('404 Not Found (error code: 10008): Unknown Message')>
Traceback (most recent call last):
  File "C:\Users\Olive\Documents\DiscordBot\venv\Lib\site-packages\discord\ext\pages\pagination.py", line 583, in on_timeout
    await self.message.edit(
  File "C:\Users\Olive\Documents\DiscordBot\venv\Lib\site-packages\discord\interactions.py", line 1194, in edit
    return await self._state._interaction.edit_original_response(
           ^^^^^^^^^^^^^^^^^^^^^^^^^^^^^^^^^^^^^^^^^^^^^^^^^^^^^^
  File "C:\Users\Olive\Documents\DiscordBot\venv\Lib\site-packages\discord\interactions.py", line 428, in edit_original_response
    data = await adapter.edit_original_interaction_response(
           ^^^^^^^^^^^^^^^^^^^^^^^^^^^^^^^^^^^^^^^^^^^^^^^^^
  File "C:\Users\Olive\Documents\DiscordBot\venv\Lib\site-packages\discord\webhook\async_.py", line 219, in request
    raise NotFound(response, data)
discord.errors.NotFound: 404 Not Found (error code: 10008): Unknown Message
